[rospy.client][INFO] 2017-09-30 12:27:06,440: init_node, name[/threshold_sender], pid[5607]
[xmlrpc][INFO] 2017-09-30 12:27:06,441: XML-RPC server binding to 0.0.0.0:0
[xmlrpc][INFO] 2017-09-30 12:27:06,442: Started XML-RPC server [http://ubuntu:44792/]
[rospy.impl.masterslave][INFO] 2017-09-30 12:27:06,442: _ready: http://ubuntu:44792/
[rospy.init][INFO] 2017-09-30 12:27:06,442: ROS Slave URI: [http://ubuntu:44792/]
[xmlrpc][INFO] 2017-09-30 12:27:06,442: xml rpc node: starting XML-RPC server
[rospy.registration][INFO] 2017-09-30 12:27:06,442: Registering with master node http://localhost:11311
[rospy.init][INFO] 2017-09-30 12:27:06,542: registered with master
[rospy.rosout][INFO] 2017-09-30 12:27:06,543: initializing /rosout core topic
[rospy.rosout][INFO] 2017-09-30 12:27:06,545: connected to core topic /rosout
[rospy.simtime][INFO] 2017-09-30 12:27:06,553: /use_sim_time is not set, will not subscribe to simulated time [/clock] topic
[rospy.internal][INFO] 2017-09-30 12:27:06,772: topic[/rosout] adding connection to [/rosout], count 0
[rospy.internal][INFO] 2017-09-30 12:27:06,908: topic[/camera/image_raw/compressed/parameter_updates] adding connection to [http://ubuntu:43887/], count 0
[rospy.internal][INFO] 2017-09-30 12:27:07,039: topic[/camera/image_raw/theora/parameter_updates] adding connection to [http://ubuntu:43887/], count 0
[rospy.internal][INFO] 2017-09-30 12:27:07,094: topic[/image/compressedDepth/parameter_updates] adding connection to [http://ubuntu:38742/], count 0
[rospy.internal][INFO] 2017-09-30 12:27:07,219: topic[/image/marked/compressedDepth/parameter_descriptions] adding connection to [http://ubuntu:46749/], count 0
[rospy.internal][INFO] 2017-09-30 12:27:07,332: topic[/image/marked/compressedDepth/parameter_updates] adding connection to [http://ubuntu:46749/], count 0
[rospy.internal][INFO] 2017-09-30 12:27:07,371: topic[/mask_orange/parameter_updates] adding connection to [http://ubuntu:38742/], count 0
[rospy.internal][INFO] 2017-09-30 12:27:07,394: topic[/image_marked/theora/parameter_updates] adding connection to [http://ubuntu:46749/], count 0
[rospy.internal][INFO] 2017-09-30 12:27:07,395: topic[/view/parameter_updates] adding connection to [http://ubuntu:46749/], count 0
[rospy.internal][INFO] 2017-09-30 12:27:07,408: topic[/image_marked/compressedDepth/parameter_updates] adding connection to [http://ubuntu:46749/], count 0
[rospy.internal][INFO] 2017-09-30 12:27:07,430: topic[/view/parameter_descriptions] adding connection to [http://ubuntu:46749/], count 0
[rospy.internal][INFO] 2017-09-30 12:27:07,439: topic[/image/theora/parameter_updates] adding connection to [http://ubuntu:38742/], count 0
[rospy.internal][INFO] 2017-09-30 12:27:07,441: topic[/image/marked/theora/parameter_updates] adding connection to [http://ubuntu:46749/], count 0
[rospy.internal][INFO] 2017-09-30 12:27:07,472: topic[/image_marked/theora/parameter_descriptions] adding connection to [http://ubuntu:46749/], count 0
[rospy.internal][INFO] 2017-09-30 12:27:07,476: topic[/image_marked/compressed/parameter_updates] adding connection to [http://ubuntu:46749/], count 0
[rospy.internal][INFO] 2017-09-30 12:27:07,483: topic[/mask_orange/parameter_descriptions] adding connection to [http://ubuntu:38742/], count 0
[rospy.internal][INFO] 2017-09-30 12:27:07,496: topic[/image/theora/parameter_descriptions] adding connection to [http://ubuntu:38742/], count 0
[rospy.internal][INFO] 2017-09-30 12:27:07,518: topic[/image_marked/compressedDepth/parameter_descriptions] adding connection to [http://ubuntu:46749/], count 0
[rospy.internal][INFO] 2017-09-30 12:27:07,524: topic[/image_marked/compressed/parameter_descriptions] adding connection to [http://ubuntu:46749/], count 0
[rospy.internal][INFO] 2017-09-30 12:27:07,541: topic[/image/marked/compressed/parameter_updates] adding connection to [http://ubuntu:46749/], count 0
[rospy.internal][INFO] 2017-09-30 12:27:07,556: topic[/image/marked/theora/parameter_descriptions] adding connection to [http://ubuntu:46749/], count 0
[rospy.internal][INFO] 2017-09-30 12:27:07,574: topic[/image/marked/compressed/parameter_descriptions] adding connection to [http://ubuntu:46749/], count 0
[rospy.internal][INFO] 2017-09-30 12:27:07,578: topic[/image/compressedDepth/parameter_descriptions] adding connection to [http://ubuntu:38742/], count 0
[rospy.internal][INFO] 2017-09-30 12:27:07,587: topic[/image/compressed/parameter_updates] adding connection to [http://ubuntu:38742/], count 0
[rospy.internal][INFO] 2017-09-30 12:27:07,616: topic[/image/compressed/parameter_descriptions] adding connection to [http://ubuntu:38742/], count 0
[rospy.internal][INFO] 2017-09-30 12:27:07,628: topic[/camera/image_raw/theora/parameter_descriptions] adding connection to [http://ubuntu:43887/], count 0
[rospy.internal][INFO] 2017-09-30 12:27:07,644: topic[/camera/image_raw/compressedDepth/parameter_updates] adding connection to [http://ubuntu:43887/], count 0
[rospy.internal][INFO] 2017-09-30 12:27:07,644: topic[/camera/image_raw/compressedDepth/parameter_descriptions] adding connection to [http://ubuntu:43887/], count 0
[rospy.internal][INFO] 2017-09-30 12:27:07,654: topic[/camera/image_raw/compressed/parameter_descriptions] adding connection to [http://ubuntu:43887/], count 0
[rospy.internal][INFO] 2017-09-30 12:29:36,098: topic impl's ref count is zero, deleting topic /mask_orange/parameter_descriptions...
[rospy.internal][INFO] 2017-09-30 12:29:36,098: topic[/mask_orange/parameter_descriptions] removing connection to http://ubuntu:38742/
[rospy.internal][INFO] 2017-09-30 12:29:36,110: topic impl's ref count is zero, deleting topic /mask_orange/parameter_updates...
[rospy.internal][INFO] 2017-09-30 12:29:36,111: topic[/mask_orange/parameter_updates] removing connection to http://ubuntu:38742/
[rospy.core][INFO] 2017-09-30 12:29:36,245: signal_shutdown [atexit]
[rospy.internal][INFO] 2017-09-30 12:29:36,389: topic[/rosout] removing connection to /rosout
[rospy.internal][INFO] 2017-09-30 12:29:36,389: topic[/image/marked/compressed/parameter_descriptions] removing connection to http://ubuntu:46749/
[rospy.internal][INFO] 2017-09-30 12:29:36,390: topic[/camera/image_raw/theora/parameter_descriptions] removing connection to http://ubuntu:43887/
[rospy.internal][INFO] 2017-09-30 12:29:36,390: topic[/image/marked/theora/parameter_descriptions] removing connection to http://ubuntu:46749/
[rospy.internal][INFO] 2017-09-30 12:29:36,390: topic[/image_marked/theora/parameter_descriptions] removing connection to http://ubuntu:46749/
[rospy.internal][INFO] 2017-09-30 12:29:36,390: topic[/image_marked/compressed/parameter_updates] removing connection to http://ubuntu:46749/
[rospy.internal][INFO] 2017-09-30 12:29:36,397: topic[/image/theora/parameter_descriptions] removing connection to http://ubuntu:38742/
[rospy.internal][WARNING] 2017-09-30 12:29:36,401: Unknown error initiating TCP/IP socket to ubuntu:57911 (http://ubuntu:43887/): Traceback (most recent call last):
  File "/opt/ros/kinetic/lib/python2.7/dist-packages/rospy/impl/tcpros_base.py", line 557, in connect
    self.read_header()
  File "/opt/ros/kinetic/lib/python2.7/dist-packages/rospy/impl/tcpros_base.py", line 650, in read_header
    self._validate_header(read_ros_handshake_header(sock, self.read_buff, self.protocol.buff_size))
  File "/opt/ros/kinetic/lib/python2.7/dist-packages/rosgraph/network.py", line 364, in read_ros_handshake_header
    raise ROSHandshakeException("connection from sender terminated before handshake header received. %s bytes were received. Please check sender for additional details."%b.tell())
ROSHandshakeException: connection from sender terminated before handshake header received. 0 bytes were received. Please check sender for additional details.

[rospy.internal][INFO] 2017-09-30 12:29:36,403: topic[/image_marked/compressedDepth/parameter_descriptions] removing connection to http://ubuntu:46749/
[rospy.internal][INFO] 2017-09-30 12:29:36,408: topic[/image/compressedDepth/parameter_updates] removing connection to http://ubuntu:38742/
[rospy.internal][WARNING] 2017-09-30 12:29:36,413: Unknown error initiating TCP/IP socket to ubuntu:57911 (http://ubuntu:43887/): Traceback (most recent call last):
  File "/opt/ros/kinetic/lib/python2.7/dist-packages/rospy/impl/tcpros_base.py", line 557, in connect
    self.read_header()
  File "/opt/ros/kinetic/lib/python2.7/dist-packages/rospy/impl/tcpros_base.py", line 650, in read_header
    self._validate_header(read_ros_handshake_header(sock, self.read_buff, self.protocol.buff_size))
  File "/opt/ros/kinetic/lib/python2.7/dist-packages/rosgraph/network.py", line 364, in read_ros_handshake_header
    raise ROSHandshakeException("connection from sender terminated before handshake header received. %s bytes were received. Please check sender for additional details."%b.tell())
ROSHandshakeException: connection from sender terminated before handshake header received. 0 bytes were received. Please check sender for additional details.

[rospy.internal][INFO] 2017-09-30 12:29:36,417: topic[/camera/image_raw/compressed/parameter_descriptions] removing connection to http://ubuntu:43887/
[rospy.internal][INFO] 2017-09-30 12:29:36,417: topic[/camera/image_raw/compressed/parameter_descriptions] removing connection to http://ubuntu:43887/
[rospy.topics][ERROR] 2017-09-30 12:29:36,423: Traceback (most recent call last):
  File "/opt/ros/kinetic/lib/python2.7/dist-packages/rospy/topics.py", line 326, in close
    c.close()
  File "/opt/ros/kinetic/lib/python2.7/dist-packages/rospy/impl/tcpros_base.py", line 838, in close
    self.socket.close()
AttributeError: 'NoneType' object has no attribute 'close'

[rospy.internal][WARNING] 2017-09-30 12:29:36,438: Unknown error initiating TCP/IP socket to ubuntu:57911 (http://ubuntu:43887/): Traceback (most recent call last):
  File "/opt/ros/kinetic/lib/python2.7/dist-packages/rospy/impl/tcpros_base.py", line 557, in connect
    self.read_header()
  File "/opt/ros/kinetic/lib/python2.7/dist-packages/rospy/impl/tcpros_base.py", line 650, in read_header
    self._validate_header(read_ros_handshake_header(sock, self.read_buff, self.protocol.buff_size))
  File "/opt/ros/kinetic/lib/python2.7/dist-packages/rosgraph/network.py", line 362, in read_ros_handshake_header
    d = sock.recv(buff_size)
error: [Errno 104] 接続が相手からリセットされました

[rospy.internal][INFO] 2017-09-30 12:29:36,439: topic[/camera/image_raw/compressedDepth/parameter_descriptions] removing connection to http://ubuntu:43887/
[rospy.internal][WARNING] 2017-09-30 12:29:36,439: Unknown error initiating TCP/IP socket to ubuntu:57911 (http://ubuntu:43887/): Traceback (most recent call last):
  File "/opt/ros/kinetic/lib/python2.7/dist-packages/rospy/impl/tcpros_base.py", line 557, in connect
    self.read_header()
  File "/opt/ros/kinetic/lib/python2.7/dist-packages/rospy/impl/tcpros_base.py", line 650, in read_header
    self._validate_header(read_ros_handshake_header(sock, self.read_buff, self.protocol.buff_size))
  File "/opt/ros/kinetic/lib/python2.7/dist-packages/rosgraph/network.py", line 362, in read_ros_handshake_header
    d = sock.recv(buff_size)
error: [Errno 104] 接続が相手からリセットされました

[rospy.internal][INFO] 2017-09-30 12:29:36,439: topic[/camera/image_raw/compressedDepth/parameter_updates] removing connection to http://ubuntu:43887/
[rospy.internal][WARNING] 2017-09-30 12:29:36,439: Unknown error initiating TCP/IP socket to ubuntu:57911 (http://ubuntu:43887/): Traceback (most recent call last):
  File "/opt/ros/kinetic/lib/python2.7/dist-packages/rospy/impl/tcpros_base.py", line 557, in connect
    self.read_header()
  File "/opt/ros/kinetic/lib/python2.7/dist-packages/rospy/impl/tcpros_base.py", line 650, in read_header
    self._validate_header(read_ros_handshake_header(sock, self.read_buff, self.protocol.buff_size))
  File "/opt/ros/kinetic/lib/python2.7/dist-packages/rosgraph/network.py", line 362, in read_ros_handshake_header
    d = sock.recv(buff_size)
error: [Errno 104] 接続が相手からリセットされました

[rospy.internal][INFO] 2017-09-30 12:29:36,439: topic[/camera/image_raw/compressed/parameter_updates] removing connection to http://ubuntu:43887/
[rospy.internal][WARNING] 2017-09-30 12:29:36,439: Unknown error initiating TCP/IP socket to ubuntu:57911 (http://ubuntu:43887/): Traceback (most recent call last):
  File "/opt/ros/kinetic/lib/python2.7/dist-packages/rospy/impl/tcpros_base.py", line 557, in connect
    self.read_header()
  File "/opt/ros/kinetic/lib/python2.7/dist-packages/rospy/impl/tcpros_base.py", line 650, in read_header
    self._validate_header(read_ros_handshake_header(sock, self.read_buff, self.protocol.buff_size))
  File "/opt/ros/kinetic/lib/python2.7/dist-packages/rosgraph/network.py", line 362, in read_ros_handshake_header
    d = sock.recv(buff_size)
error: [Errno 104] 接続が相手からリセットされました

[rospy.internal][INFO] 2017-09-30 12:29:36,439: topic[/camera/image_raw/theora/parameter_updates] removing connection to http://ubuntu:43887/
[rospy.internal][INFO] 2017-09-30 12:29:36,438: topic[/image_marked/compressedDepth/parameter_updates] removing connection to http://ubuntu:46749/
[rospy.internal][INFO] 2017-09-30 12:29:36,442: topic[/image/compressed/parameter_descriptions] removing connection to http://ubuntu:38742/
[rospy.internal][INFO] 2017-09-30 12:29:36,443: topic[/image/marked/theora/parameter_updates] removing connection to http://ubuntu:46749/
[rospy.internal][INFO] 2017-09-30 12:29:36,445: topic[/image/compressedDepth/parameter_descriptions] removing connection to http://ubuntu:38742/
[rospy.internal][INFO] 2017-09-30 12:29:36,446: topic[/image/marked/compressedDepth/parameter_descriptions] removing connection to http://ubuntu:46749/
[rospy.internal][INFO] 2017-09-30 12:29:36,446: topic[/view/parameter_updates] removing connection to http://ubuntu:46749/
[rospy.internal][INFO] 2017-09-30 12:29:36,446: topic[/image_marked/theora/parameter_updates] removing connection to http://ubuntu:46749/
[rospy.internal][INFO] 2017-09-30 12:29:36,449: topic[/image/marked/compressed/parameter_updates] removing connection to http://ubuntu:46749/
[rospy.internal][INFO] 2017-09-30 12:29:36,449: topic[/image/marked/compressedDepth/parameter_updates] removing connection to http://ubuntu:46749/
[rospy.internal][INFO] 2017-09-30 12:29:36,455: topic[/view/parameter_descriptions] removing connection to http://ubuntu:46749/
[rospy.internal][INFO] 2017-09-30 12:29:36,455: topic[/image/compressed/parameter_updates] removing connection to http://ubuntu:38742/
[rospy.internal][INFO] 2017-09-30 12:29:36,463: topic[/image_marked/compressed/parameter_descriptions] removing connection to http://ubuntu:46749/
[rospy.internal][INFO] 2017-09-30 12:29:36,475: topic[/image/theora/parameter_updates] removing connection to http://ubuntu:38742/
[rospy.impl.masterslave][INFO] 2017-09-30 12:29:36,475: atexit
[rospy.internal][WARNING] 2017-09-30 12:29:36,621: Unknown error initiating TCP/IP socket to ubuntu:46047 (http://ubuntu:38742/): Traceback (most recent call last):
  File "/opt/ros/kinetic/lib/python2.7/dist-packages/rospy/impl/tcpros_base.py", line 557, in connect
    self.read_header()
  File "/opt/ros/kinetic/lib/python2.7/dist-packages/rospy/impl/tcpros_base.py", line 650, in read_header
    self._validate_header(read_ros_handshake_header(sock, self.read_buff, self.protocol.buff_size))
  File "/opt/ros/kinetic/lib/python2.7/dist-packages/rosgraph/network.py", line 362, in read_ros_handshake_header
    d = sock.recv(buff_size)
error: [Errno 104] 接続が相手からリセットされました

[rospy.internal][WARNING] 2017-09-30 12:29:36,621: Unknown error initiating TCP/IP socket to ubuntu:46047 (http://ubuntu:38742/): Traceback (most recent call last):
  File "/opt/ros/kinetic/lib/python2.7/dist-packages/rospy/impl/tcpros_base.py", line 557, in connect
    self.read_header()
  File "/opt/ros/kinetic/lib/python2.7/dist-packages/rospy/impl/tcpros_base.py", line 650, in read_header
    self._validate_header(read_ros_handshake_header(sock, self.read_buff, self.protocol.buff_size))
  File "/opt/ros/kinetic/lib/python2.7/dist-packages/rosgraph/network.py", line 362, in read_ros_handshake_header
    d = sock.recv(buff_size)
error: [Errno 104] 接続が相手からリセットされました

[rospy.internal][WARNING] 2017-09-30 12:29:36,621: Unknown error initiating TCP/IP socket to ubuntu:46047 (http://ubuntu:38742/): Traceback (most recent call last):
  File "/opt/ros/kinetic/lib/python2.7/dist-packages/rospy/impl/tcpros_base.py", line 557, in connect
    self.read_header()
  File "/opt/ros/kinetic/lib/python2.7/dist-packages/rospy/impl/tcpros_base.py", line 650, in read_header
    self._validate_header(read_ros_handshake_header(sock, self.read_buff, self.protocol.buff_size))
  File "/opt/ros/kinetic/lib/python2.7/dist-packages/rosgraph/network.py", line 362, in read_ros_handshake_header
    d = sock.recv(buff_size)
error: [Errno 104] 接続が相手からリセットされました

[rospy.internal][WARNING] 2017-09-30 12:29:36,622: Unknown error initiating TCP/IP socket to ubuntu:46047 (http://ubuntu:38742/): Traceback (most recent call last):
  File "/opt/ros/kinetic/lib/python2.7/dist-packages/rospy/impl/tcpros_base.py", line 557, in connect
    self.read_header()
  File "/opt/ros/kinetic/lib/python2.7/dist-packages/rospy/impl/tcpros_base.py", line 650, in read_header
    self._validate_header(read_ros_handshake_header(sock, self.read_buff, self.protocol.buff_size))
  File "/opt/ros/kinetic/lib/python2.7/dist-packages/rosgraph/network.py", line 362, in read_ros_handshake_header
    d = sock.recv(buff_size)
error: [Errno 104] 接続が相手からリセットされました

[rospy.internal][WARNING] 2017-09-30 12:29:36,622: Unknown error initiating TCP/IP socket to ubuntu:46047 (http://ubuntu:38742/): Traceback (most recent call last):
  File "/opt/ros/kinetic/lib/python2.7/dist-packages/rospy/impl/tcpros_base.py", line 557, in connect
    self.read_header()
  File "/opt/ros/kinetic/lib/python2.7/dist-packages/rospy/impl/tcpros_base.py", line 650, in read_header
    self._validate_header(read_ros_handshake_header(sock, self.read_buff, self.protocol.buff_size))
  File "/opt/ros/kinetic/lib/python2.7/dist-packages/rosgraph/network.py", line 362, in read_ros_handshake_header
    d = sock.recv(buff_size)
error: [Errno 104] 接続が相手からリセットされました

[rospy.internal][WARNING] 2017-09-30 12:29:36,622: Unknown error initiating TCP/IP socket to ubuntu:46047 (http://ubuntu:38742/): Traceback (most recent call last):
  File "/opt/ros/kinetic/lib/python2.7/dist-packages/rospy/impl/tcpros_base.py", line 557, in connect
    self.read_header()
  File "/opt/ros/kinetic/lib/python2.7/dist-packages/rospy/impl/tcpros_base.py", line 650, in read_header
    self._validate_header(read_ros_handshake_header(sock, self.read_buff, self.protocol.buff_size))
  File "/opt/ros/kinetic/lib/python2.7/dist-packages/rosgraph/network.py", line 362, in read_ros_handshake_header
    d = sock.recv(buff_size)
error: [Errno 104] 接続が相手からリセットされました

[rospy.internal][WARNING] 2017-09-30 12:29:36,622: Unknown error initiating TCP/IP socket to ubuntu:46047 (http://ubuntu:38742/): Traceback (most recent call last):
  File "/opt/ros/kinetic/lib/python2.7/dist-packages/rospy/impl/tcpros_base.py", line 557, in connect
    self.read_header()
  File "/opt/ros/kinetic/lib/python2.7/dist-packages/rospy/impl/tcpros_base.py", line 650, in read_header
    self._validate_header(read_ros_handshake_header(sock, self.read_buff, self.protocol.buff_size))
  File "/opt/ros/kinetic/lib/python2.7/dist-packages/rosgraph/network.py", line 362, in read_ros_handshake_header
    d = sock.recv(buff_size)
error: [Errno 104] 接続が相手からリセットされました

[rospy.internal][WARNING] 2017-09-30 12:29:36,622: Unknown error initiating TCP/IP socket to ubuntu:46047 (http://ubuntu:38742/): Traceback (most recent call last):
  File "/opt/ros/kinetic/lib/python2.7/dist-packages/rospy/impl/tcpros_base.py", line 557, in connect
    self.read_header()
  File "/opt/ros/kinetic/lib/python2.7/dist-packages/rospy/impl/tcpros_base.py", line 650, in read_header
    self._validate_header(read_ros_handshake_header(sock, self.read_buff, self.protocol.buff_size))
  File "/opt/ros/kinetic/lib/python2.7/dist-packages/rosgraph/network.py", line 362, in read_ros_handshake_header
    d = sock.recv(buff_size)
error: [Errno 104] 接続が相手からリセットされました

[rospy.internal][WARNING] 2017-09-30 12:29:36,704: Unknown error initiating TCP/IP socket to ubuntu:41752 (http://ubuntu:46749/): Traceback (most recent call last):
  File "/opt/ros/kinetic/lib/python2.7/dist-packages/rospy/impl/tcpros_base.py", line 557, in connect
    self.read_header()
  File "/opt/ros/kinetic/lib/python2.7/dist-packages/rospy/impl/tcpros_base.py", line 650, in read_header
    self._validate_header(read_ros_handshake_header(sock, self.read_buff, self.protocol.buff_size))
  File "/opt/ros/kinetic/lib/python2.7/dist-packages/rosgraph/network.py", line 362, in read_ros_handshake_header
    d = sock.recv(buff_size)
error: [Errno 104] 接続が相手からリセットされました

[rospy.internal][WARNING] 2017-09-30 12:29:36,704: Unknown error initiating TCP/IP socket to ubuntu:41752 (http://ubuntu:46749/): Traceback (most recent call last):
  File "/opt/ros/kinetic/lib/python2.7/dist-packages/rospy/impl/tcpros_base.py", line 557, in connect
    self.read_header()
  File "/opt/ros/kinetic/lib/python2.7/dist-packages/rospy/impl/tcpros_base.py", line 650, in read_header
    self._validate_header(read_ros_handshake_header(sock, self.read_buff, self.protocol.buff_size))
  File "/opt/ros/kinetic/lib/python2.7/dist-packages/rosgraph/network.py", line 362, in read_ros_handshake_header
    d = sock.recv(buff_size)
error: [Errno 104] 接続が相手からリセットされました

[rospy.internal][WARNING] 2017-09-30 12:29:36,704: Unknown error initiating TCP/IP socket to ubuntu:41752 (http://ubuntu:46749/): Traceback (most recent call last):
  File "/opt/ros/kinetic/lib/python2.7/dist-packages/rospy/impl/tcpros_base.py", line 557, in connect
    self.read_header()
  File "/opt/ros/kinetic/lib/python2.7/dist-packages/rospy/impl/tcpros_base.py", line 650, in read_header
    self._validate_header(read_ros_handshake_header(sock, self.read_buff, self.protocol.buff_size))
  File "/opt/ros/kinetic/lib/python2.7/dist-packages/rosgraph/network.py", line 362, in read_ros_handshake_header
    d = sock.recv(buff_size)
error: [Errno 104] 接続が相手からリセットされました

[rospy.internal][WARNING] 2017-09-30 12:29:36,705: Unknown error initiating TCP/IP socket to ubuntu:41752 (http://ubuntu:46749/): Traceback (most recent call last):
  File "/opt/ros/kinetic/lib/python2.7/dist-packages/rospy/impl/tcpros_base.py", line 557, in connect
    self.read_header()
  File "/opt/ros/kinetic/lib/python2.7/dist-packages/rospy/impl/tcpros_base.py", line 650, in read_header
    self._validate_header(read_ros_handshake_header(sock, self.read_buff, self.protocol.buff_size))
  File "/opt/ros/kinetic/lib/python2.7/dist-packages/rosgraph/network.py", line 362, in read_ros_handshake_header
    d = sock.recv(buff_size)
error: [Errno 104] 接続が相手からリセットされました

[rospy.internal][WARNING] 2017-09-30 12:29:36,705: Unknown error initiating TCP/IP socket to ubuntu:41752 (http://ubuntu:46749/): Traceback (most recent call last):
  File "/opt/ros/kinetic/lib/python2.7/dist-packages/rospy/impl/tcpros_base.py", line 557, in connect
    self.read_header()
  File "/opt/ros/kinetic/lib/python2.7/dist-packages/rospy/impl/tcpros_base.py", line 650, in read_header
    self._validate_header(read_ros_handshake_header(sock, self.read_buff, self.protocol.buff_size))
  File "/opt/ros/kinetic/lib/python2.7/dist-packages/rosgraph/network.py", line 362, in read_ros_handshake_header
    d = sock.recv(buff_size)
error: [Errno 104] 接続が相手からリセットされました

[rospy.internal][WARNING] 2017-09-30 12:29:36,705: Unknown error initiating TCP/IP socket to ubuntu:41752 (http://ubuntu:46749/): Traceback (most recent call last):
  File "/opt/ros/kinetic/lib/python2.7/dist-packages/rospy/impl/tcpros_base.py", line 557, in connect
    self.read_header()
  File "/opt/ros/kinetic/lib/python2.7/dist-packages/rospy/impl/tcpros_base.py", line 650, in read_header
    self._validate_header(read_ros_handshake_header(sock, self.read_buff, self.protocol.buff_size))
  File "/opt/ros/kinetic/lib/python2.7/dist-packages/rosgraph/network.py", line 362, in read_ros_handshake_header
    d = sock.recv(buff_size)
error: [Errno 104] 接続が相手からリセットされました

[rospy.internal][WARNING] 2017-09-30 12:29:36,705: Unknown error initiating TCP/IP socket to ubuntu:41752 (http://ubuntu:46749/): Traceback (most recent call last):
  File "/opt/ros/kinetic/lib/python2.7/dist-packages/rospy/impl/tcpros_base.py", line 557, in connect
    self.read_header()
  File "/opt/ros/kinetic/lib/python2.7/dist-packages/rospy/impl/tcpros_base.py", line 650, in read_header
    self._validate_header(read_ros_handshake_header(sock, self.read_buff, self.protocol.buff_size))
  File "/opt/ros/kinetic/lib/python2.7/dist-packages/rosgraph/network.py", line 362, in read_ros_handshake_header
    d = sock.recv(buff_size)
error: [Errno 104] 接続が相手からリセットされました

[rospy.internal][WARNING] 2017-09-30 12:29:36,705: Unknown error initiating TCP/IP socket to ubuntu:41752 (http://ubuntu:46749/): Traceback (most recent call last):
  File "/opt/ros/kinetic/lib/python2.7/dist-packages/rospy/impl/tcpros_base.py", line 557, in connect
    self.read_header()
  File "/opt/ros/kinetic/lib/python2.7/dist-packages/rospy/impl/tcpros_base.py", line 650, in read_header
    self._validate_header(read_ros_handshake_header(sock, self.read_buff, self.protocol.buff_size))
  File "/opt/ros/kinetic/lib/python2.7/dist-packages/rosgraph/network.py", line 362, in read_ros_handshake_header
    d = sock.recv(buff_size)
error: [Errno 104] 接続が相手からリセットされました

[rospy.internal][WARNING] 2017-09-30 12:29:36,705: Unknown error initiating TCP/IP socket to ubuntu:41752 (http://ubuntu:46749/): Traceback (most recent call last):
  File "/opt/ros/kinetic/lib/python2.7/dist-packages/rospy/impl/tcpros_base.py", line 557, in connect
    self.read_header()
  File "/opt/ros/kinetic/lib/python2.7/dist-packages/rospy/impl/tcpros_base.py", line 650, in read_header
    self._validate_header(read_ros_handshake_header(sock, self.read_buff, self.protocol.buff_size))
  File "/opt/ros/kinetic/lib/python2.7/dist-packages/rosgraph/network.py", line 362, in read_ros_handshake_header
    d = sock.recv(buff_size)
error: [Errno 104] 接続が相手からリセットされました

[rospy.internal][WARNING] 2017-09-30 12:29:36,705: Unknown error initiating TCP/IP socket to ubuntu:41752 (http://ubuntu:46749/): Traceback (most recent call last):
  File "/opt/ros/kinetic/lib/python2.7/dist-packages/rospy/impl/tcpros_base.py", line 557, in connect
    self.read_header()
  File "/opt/ros/kinetic/lib/python2.7/dist-packages/rospy/impl/tcpros_base.py", line 650, in read_header
    self._validate_header(read_ros_handshake_header(sock, self.read_buff, self.protocol.buff_size))
  File "/opt/ros/kinetic/lib/python2.7/dist-packages/rosgraph/network.py", line 362, in read_ros_handshake_header
    d = sock.recv(buff_size)
error: [Errno 104] 接続が相手からリセットされました

[rospy.internal][WARNING] 2017-09-30 12:29:36,706: Unknown error initiating TCP/IP socket to ubuntu:41752 (http://ubuntu:46749/): Traceback (most recent call last):
  File "/opt/ros/kinetic/lib/python2.7/dist-packages/rospy/impl/tcpros_base.py", line 557, in connect
    self.read_header()
  File "/opt/ros/kinetic/lib/python2.7/dist-packages/rospy/impl/tcpros_base.py", line 650, in read_header
    self._validate_header(read_ros_handshake_header(sock, self.read_buff, self.protocol.buff_size))
  File "/opt/ros/kinetic/lib/python2.7/dist-packages/rosgraph/network.py", line 362, in read_ros_handshake_header
    d = sock.recv(buff_size)
error: [Errno 104] 接続が相手からリセットされました

[rospy.internal][WARNING] 2017-09-30 12:29:36,706: Unknown error initiating TCP/IP socket to ubuntu:41752 (http://ubuntu:46749/): Traceback (most recent call last):
  File "/opt/ros/kinetic/lib/python2.7/dist-packages/rospy/impl/tcpros_base.py", line 557, in connect
    self.read_header()
  File "/opt/ros/kinetic/lib/python2.7/dist-packages/rospy/impl/tcpros_base.py", line 650, in read_header
    self._validate_header(read_ros_handshake_header(sock, self.read_buff, self.protocol.buff_size))
  File "/opt/ros/kinetic/lib/python2.7/dist-packages/rosgraph/network.py", line 362, in read_ros_handshake_header
    d = sock.recv(buff_size)
error: [Errno 104] 接続が相手からリセットされました

[rospy.internal][WARNING] 2017-09-30 12:29:36,706: Unknown error initiating TCP/IP socket to ubuntu:41752 (http://ubuntu:46749/): Traceback (most recent call last):
  File "/opt/ros/kinetic/lib/python2.7/dist-packages/rospy/impl/tcpros_base.py", line 557, in connect
    self.read_header()
  File "/opt/ros/kinetic/lib/python2.7/dist-packages/rospy/impl/tcpros_base.py", line 650, in read_header
    self._validate_header(read_ros_handshake_header(sock, self.read_buff, self.protocol.buff_size))
  File "/opt/ros/kinetic/lib/python2.7/dist-packages/rosgraph/network.py", line 362, in read_ros_handshake_header
    d = sock.recv(buff_size)
error: [Errno 104] 接続が相手からリセットされました

[rospy.internal][WARNING] 2017-09-30 12:29:36,706: Unknown error initiating TCP/IP socket to ubuntu:41752 (http://ubuntu:46749/): Traceback (most recent call last):
  File "/opt/ros/kinetic/lib/python2.7/dist-packages/rospy/impl/tcpros_base.py", line 557, in connect
    self.read_header()
  File "/opt/ros/kinetic/lib/python2.7/dist-packages/rospy/impl/tcpros_base.py", line 650, in read_header
    self._validate_header(read_ros_handshake_header(sock, self.read_buff, self.protocol.buff_size))
  File "/opt/ros/kinetic/lib/python2.7/dist-packages/rosgraph/network.py", line 362, in read_ros_handshake_header
    d = sock.recv(buff_size)
error: [Errno 104] 接続が相手からリセットされました

