[rospy.client][INFO] 2017-10-04 17:26:05,816: init_node, name[/threshold_sender], pid[7881]
[xmlrpc][INFO] 2017-10-04 17:26:05,817: XML-RPC server binding to 0.0.0.0:0
[xmlrpc][INFO] 2017-10-04 17:26:05,817: Started XML-RPC server [http://ubuntu:33174/]
[rospy.init][INFO] 2017-10-04 17:26:05,817: ROS Slave URI: [http://ubuntu:33174/]
[rospy.impl.masterslave][INFO] 2017-10-04 17:26:05,817: _ready: http://ubuntu:33174/
[xmlrpc][INFO] 2017-10-04 17:26:05,818: xml rpc node: starting XML-RPC server
[rospy.registration][INFO] 2017-10-04 17:26:05,818: Registering with master node http://localhost:11311
[rospy.init][INFO] 2017-10-04 17:26:05,918: registered with master
[rospy.rosout][INFO] 2017-10-04 17:26:05,918: initializing /rosout core topic
[rospy.rosout][INFO] 2017-10-04 17:26:05,920: connected to core topic /rosout
[rospy.simtime][INFO] 2017-10-04 17:26:05,921: /use_sim_time is not set, will not subscribe to simulated time [/clock] topic
[rospy.internal][INFO] 2017-10-04 17:26:06,152: topic[/image/compressed/parameter_descriptions] adding connection to [http://ubuntu:38855/], count 0
[rospy.internal][INFO] 2017-10-04 17:26:06,159: topic[/rosout] adding connection to [/rosout], count 0
[rospy.internal][INFO] 2017-10-04 17:26:06,201: topic[/image/marked/compressed/parameter_descriptions] adding connection to [http://ubuntu:38779/], count 0
[rospy.internal][INFO] 2017-10-04 17:26:06,252: topic[/image/marked/theora/parameter_descriptions] adding connection to [http://ubuntu:38779/], count 0
[rospy.internal][INFO] 2017-10-04 17:26:06,267: topic[/image_marked/compressedDepth/parameter_descriptions] adding connection to [http://ubuntu:38779/], count 0
[rospy.internal][INFO] 2017-10-04 17:26:06,293: topic[/image/theora/parameter_updates] adding connection to [http://ubuntu:38855/], count 0
[rospy.internal][INFO] 2017-10-04 17:26:06,302: topic[/view/parameter_descriptions] adding connection to [http://ubuntu:38779/], count 0
[rospy.internal][INFO] 2017-10-04 17:26:06,322: topic[/view/parameter_updates] adding connection to [http://ubuntu:38779/], count 0
[rospy.internal][INFO] 2017-10-04 17:26:06,328: topic[/mask_orange/parameter_updates] adding connection to [http://ubuntu:38855/], count 0
[rospy.internal][INFO] 2017-10-04 17:26:06,348: topic[/mask_orange/parameter_descriptions] adding connection to [http://ubuntu:38855/], count 0
[rospy.internal][INFO] 2017-10-04 17:26:06,367: topic[/image_marked/theora/parameter_updates] adding connection to [http://ubuntu:38779/], count 0
[rospy.internal][INFO] 2017-10-04 17:26:06,383: topic[/image_marked/theora/parameter_descriptions] adding connection to [http://ubuntu:38779/], count 0
[rospy.internal][INFO] 2017-10-04 17:26:06,388: topic[/image_marked/compressed/parameter_updates] adding connection to [http://ubuntu:38779/], count 0
[rospy.internal][INFO] 2017-10-04 17:26:06,398: topic[/image_marked/compressedDepth/parameter_updates] adding connection to [http://ubuntu:38779/], count 0
[rospy.internal][INFO] 2017-10-04 17:26:06,408: topic[/image_marked/compressed/parameter_descriptions] adding connection to [http://ubuntu:38779/], count 0
[rospy.internal][INFO] 2017-10-04 17:26:06,409: topic[/image/marked/theora/parameter_updates] adding connection to [http://ubuntu:38779/], count 0
[rospy.internal][INFO] 2017-10-04 17:26:06,420: topic[/image/marked/compressedDepth/parameter_updates] adding connection to [http://ubuntu:38779/], count 0
[rospy.internal][INFO] 2017-10-04 17:26:06,421: topic[/image/theora/parameter_descriptions] adding connection to [http://ubuntu:38855/], count 0
[rospy.internal][INFO] 2017-10-04 17:26:06,428: topic[/image/marked/compressedDepth/parameter_descriptions] adding connection to [http://ubuntu:38779/], count 0
[rospy.internal][INFO] 2017-10-04 17:26:06,438: topic[/image/marked/compressed/parameter_updates] adding connection to [http://ubuntu:38779/], count 0
[rospy.internal][INFO] 2017-10-04 17:26:06,458: topic[/image/compressedDepth/parameter_updates] adding connection to [http://ubuntu:38855/], count 0
[rospy.internal][INFO] 2017-10-04 17:26:06,464: topic[/image/compressedDepth/parameter_descriptions] adding connection to [http://ubuntu:38855/], count 0
[rospy.internal][INFO] 2017-10-04 17:26:06,469: topic[/camera/image_raw/theora/parameter_updates] adding connection to [http://ubuntu:43512/], count 0
[rospy.internal][INFO] 2017-10-04 17:26:06,472: topic[/image/compressed/parameter_updates] adding connection to [http://ubuntu:38855/], count 0
[rospy.internal][INFO] 2017-10-04 17:26:06,492: topic[/camera/image_raw/compressed/parameter_updates] adding connection to [http://ubuntu:43512/], count 0
[rospy.internal][INFO] 2017-10-04 17:26:06,493: topic[/camera/image_raw/theora/parameter_descriptions] adding connection to [http://ubuntu:43512/], count 0
[rospy.internal][INFO] 2017-10-04 17:26:06,534: topic[/camera/image_raw/compressedDepth/parameter_updates] adding connection to [http://ubuntu:43512/], count 0
[rospy.internal][INFO] 2017-10-04 17:26:06,555: topic[/camera/image_raw/compressedDepth/parameter_descriptions] adding connection to [http://ubuntu:43512/], count 0
[rospy.internal][INFO] 2017-10-04 17:26:06,567: topic[/camera/image_raw/compressed/parameter_descriptions] adding connection to [http://ubuntu:43512/], count 0
[rospy.internal][INFO] 2017-10-04 17:55:50,347: topic impl's ref count is zero, deleting topic /mask_orange/parameter_descriptions...
[rospy.internal][INFO] 2017-10-04 17:55:50,359: topic[/mask_orange/parameter_descriptions] removing connection to http://ubuntu:38855/
[rospy.internal][INFO] 2017-10-04 17:55:50,362: topic impl's ref count is zero, deleting topic /mask_orange/parameter_updates...
[rospy.internal][INFO] 2017-10-04 17:55:50,363: topic[/mask_orange/parameter_updates] removing connection to http://ubuntu:38855/
[rospy.core][INFO] 2017-10-04 17:55:50,454: signal_shutdown [atexit]
[rospy.internal][INFO] 2017-10-04 17:55:50,516: topic[/rosout] removing connection to /rosout
[rospy.internal][INFO] 2017-10-04 17:55:50,517: topic[/image/marked/compressed/parameter_descriptions] removing connection to http://ubuntu:38779/
[rospy.internal][INFO] 2017-10-04 17:55:50,518: topic[/camera/image_raw/theora/parameter_descriptions] removing connection to http://ubuntu:43512/
[rospy.internal][INFO] 2017-10-04 17:55:50,518: topic[/image/marked/theora/parameter_descriptions] removing connection to http://ubuntu:38779/
[rospy.internal][INFO] 2017-10-04 17:55:50,525: topic[/image/marked/compressedDepth/parameter_descriptions] removing connection to http://ubuntu:38779/
[rospy.internal][INFO] 2017-10-04 17:55:50,525: topic[/image_marked/theora/parameter_descriptions] removing connection to http://ubuntu:38779/
[rospy.internal][INFO] 2017-10-04 17:55:50,537: topic[/image_marked/compressed/parameter_updates] removing connection to http://ubuntu:38779/
[rospy.internal][INFO] 2017-10-04 17:55:50,538: topic[/image/theora/parameter_descriptions] removing connection to http://ubuntu:38855/
[rospy.internal][INFO] 2017-10-04 17:55:50,543: topic[/image_marked/compressedDepth/parameter_descriptions] removing connection to http://ubuntu:38779/
[rospy.internal][INFO] 2017-10-04 17:55:50,549: topic[/image/compressedDepth/parameter_updates] removing connection to http://ubuntu:38855/
[rospy.internal][WARNING] 2017-10-04 17:55:50,550: Unknown error initiating TCP/IP socket to ubuntu:53854 (http://ubuntu:43512/): Traceback (most recent call last):
  File "/opt/ros/kinetic/lib/python2.7/dist-packages/rospy/impl/tcpros_base.py", line 557, in connect
    self.read_header()
  File "/opt/ros/kinetic/lib/python2.7/dist-packages/rospy/impl/tcpros_base.py", line 650, in read_header
    self._validate_header(read_ros_handshake_header(sock, self.read_buff, self.protocol.buff_size))
  File "/opt/ros/kinetic/lib/python2.7/dist-packages/rosgraph/network.py", line 364, in read_ros_handshake_header
    raise ROSHandshakeException("connection from sender terminated before handshake header received. %s bytes were received. Please check sender for additional details."%b.tell())
ROSHandshakeException: connection from sender terminated before handshake header received. 0 bytes were received. Please check sender for additional details.

[rospy.internal][INFO] 2017-10-04 17:55:50,551: topic[/camera/image_raw/compressed/parameter_descriptions] removing connection to http://ubuntu:43512/
[rospy.internal][INFO] 2017-10-04 17:55:50,563: topic[/camera/image_raw/compressed/parameter_descriptions] removing connection to http://ubuntu:43512/
[rospy.topics][ERROR] 2017-10-04 17:55:50,563: Traceback (most recent call last):
  File "/opt/ros/kinetic/lib/python2.7/dist-packages/rospy/topics.py", line 326, in close
    c.close()
  File "/opt/ros/kinetic/lib/python2.7/dist-packages/rospy/impl/tcpros_base.py", line 838, in close
    self.socket.close()
AttributeError: 'NoneType' object has no attribute 'close'

[rospy.internal][INFO] 2017-10-04 17:55:50,572: topic[/image_marked/compressedDepth/parameter_updates] removing connection to http://ubuntu:38779/
[rospy.internal][INFO] 2017-10-04 17:55:50,573: topic[/image/compressed/parameter_descriptions] removing connection to http://ubuntu:38855/
[rospy.internal][INFO] 2017-10-04 17:55:50,588: topic[/image/marked/theora/parameter_updates] removing connection to http://ubuntu:38779/
[rospy.internal][INFO] 2017-10-04 17:55:50,590: topic[/image/compressedDepth/parameter_descriptions] removing connection to http://ubuntu:38855/
[rospy.internal][WARNING] 2017-10-04 17:55:50,596: Unknown error initiating TCP/IP socket to ubuntu:53854 (http://ubuntu:43512/): Traceback (most recent call last):
  File "/opt/ros/kinetic/lib/python2.7/dist-packages/rospy/impl/tcpros_base.py", line 557, in connect
    self.read_header()
  File "/opt/ros/kinetic/lib/python2.7/dist-packages/rospy/impl/tcpros_base.py", line 650, in read_header
    self._validate_header(read_ros_handshake_header(sock, self.read_buff, self.protocol.buff_size))
  File "/opt/ros/kinetic/lib/python2.7/dist-packages/rosgraph/network.py", line 364, in read_ros_handshake_header
    raise ROSHandshakeException("connection from sender terminated before handshake header received. %s bytes were received. Please check sender for additional details."%b.tell())
ROSHandshakeException: connection from sender terminated before handshake header received. 0 bytes were received. Please check sender for additional details.

[rospy.internal][INFO] 2017-10-04 17:55:50,597: topic[/camera/image_raw/compressedDepth/parameter_descriptions] removing connection to http://ubuntu:43512/
[rospy.internal][INFO] 2017-10-04 17:55:50,597: topic[/camera/image_raw/compressedDepth/parameter_descriptions] removing connection to http://ubuntu:43512/
[rospy.topics][ERROR] 2017-10-04 17:55:50,597: Traceback (most recent call last):
  File "/opt/ros/kinetic/lib/python2.7/dist-packages/rospy/topics.py", line 326, in close
    c.close()
  File "/opt/ros/kinetic/lib/python2.7/dist-packages/rospy/impl/tcpros_base.py", line 838, in close
    self.socket.close()
AttributeError: 'NoneType' object has no attribute 'close'

[rospy.internal][WARNING] 2017-10-04 17:55:50,597: Unknown error initiating TCP/IP socket to ubuntu:53854 (http://ubuntu:43512/): Traceback (most recent call last):
  File "/opt/ros/kinetic/lib/python2.7/dist-packages/rospy/impl/tcpros_base.py", line 557, in connect
    self.read_header()
  File "/opt/ros/kinetic/lib/python2.7/dist-packages/rospy/impl/tcpros_base.py", line 650, in read_header
    self._validate_header(read_ros_handshake_header(sock, self.read_buff, self.protocol.buff_size))
  File "/opt/ros/kinetic/lib/python2.7/dist-packages/rosgraph/network.py", line 364, in read_ros_handshake_header
    raise ROSHandshakeException("connection from sender terminated before handshake header received. %s bytes were received. Please check sender for additional details."%b.tell())
ROSHandshakeException: connection from sender terminated before handshake header received. 0 bytes were received. Please check sender for additional details.

[rospy.internal][INFO] 2017-10-04 17:55:50,597: topic[/camera/image_raw/compressedDepth/parameter_updates] removing connection to http://ubuntu:43512/
[rospy.internal][INFO] 2017-10-04 17:55:50,597: topic[/camera/image_raw/compressedDepth/parameter_updates] removing connection to http://ubuntu:43512/
[rospy.topics][ERROR] 2017-10-04 17:55:50,597: Traceback (most recent call last):
  File "/opt/ros/kinetic/lib/python2.7/dist-packages/rospy/topics.py", line 326, in close
    c.close()
  File "/opt/ros/kinetic/lib/python2.7/dist-packages/rospy/impl/tcpros_base.py", line 838, in close
    self.socket.close()
AttributeError: 'NoneType' object has no attribute 'close'

[rospy.internal][INFO] 2017-10-04 17:55:50,600: topic[/camera/image_raw/theora/parameter_updates] removing connection to http://ubuntu:43512/
[rospy.internal][WARNING] 2017-10-04 17:55:50,601: Unknown error initiating TCP/IP socket to ubuntu:53854 (http://ubuntu:43512/): Traceback (most recent call last):
  File "/opt/ros/kinetic/lib/python2.7/dist-packages/rospy/impl/tcpros_base.py", line 557, in connect
    self.read_header()
  File "/opt/ros/kinetic/lib/python2.7/dist-packages/rospy/impl/tcpros_base.py", line 650, in read_header
    self._validate_header(read_ros_handshake_header(sock, self.read_buff, self.protocol.buff_size))
  File "/opt/ros/kinetic/lib/python2.7/dist-packages/rosgraph/network.py", line 364, in read_ros_handshake_header
    raise ROSHandshakeException("connection from sender terminated before handshake header received. %s bytes were received. Please check sender for additional details."%b.tell())
ROSHandshakeException: connection from sender terminated before handshake header received. 0 bytes were received. Please check sender for additional details.

[rospy.internal][INFO] 2017-10-04 17:55:50,601: topic[/camera/image_raw/compressed/parameter_updates] removing connection to http://ubuntu:43512/
[rospy.internal][INFO] 2017-10-04 17:55:50,601: topic[/camera/image_raw/compressed/parameter_updates] removing connection to http://ubuntu:43512/
[rospy.topics][ERROR] 2017-10-04 17:55:50,601: Traceback (most recent call last):
  File "/opt/ros/kinetic/lib/python2.7/dist-packages/rospy/topics.py", line 326, in close
    c.close()
  File "/opt/ros/kinetic/lib/python2.7/dist-packages/rospy/impl/tcpros_base.py", line 838, in close
    self.socket.close()
AttributeError: 'NoneType' object has no attribute 'close'

[rospy.internal][INFO] 2017-10-04 17:55:50,601: topic[/view/parameter_updates] removing connection to http://ubuntu:38779/
[rospy.internal][INFO] 2017-10-04 17:55:50,602: topic[/image_marked/theora/parameter_updates] removing connection to http://ubuntu:38779/
[rospy.internal][INFO] 2017-10-04 17:55:50,605: topic[/image/marked/compressed/parameter_updates] removing connection to http://ubuntu:38779/
[rospy.internal][INFO] 2017-10-04 17:55:50,605: topic[/image/marked/compressedDepth/parameter_updates] removing connection to http://ubuntu:38779/
[rospy.internal][INFO] 2017-10-04 17:55:50,613: topic[/view/parameter_descriptions] removing connection to http://ubuntu:38779/
[rospy.internal][INFO] 2017-10-04 17:55:50,613: topic[/image/compressed/parameter_updates] removing connection to http://ubuntu:38855/
[rospy.internal][INFO] 2017-10-04 17:55:50,613: topic[/image_marked/compressed/parameter_descriptions] removing connection to http://ubuntu:38779/
[rospy.internal][INFO] 2017-10-04 17:55:50,614: topic[/image/theora/parameter_updates] removing connection to http://ubuntu:38855/
[rospy.impl.masterslave][INFO] 2017-10-04 17:55:50,614: atexit
[rospy.internal][WARNING] 2017-10-04 17:55:50,653: Unknown error initiating TCP/IP socket to ubuntu:53854 (http://ubuntu:43512/): Traceback (most recent call last):
  File "/opt/ros/kinetic/lib/python2.7/dist-packages/rospy/impl/tcpros_base.py", line 557, in connect
    self.read_header()
  File "/opt/ros/kinetic/lib/python2.7/dist-packages/rospy/impl/tcpros_base.py", line 650, in read_header
    self._validate_header(read_ros_handshake_header(sock, self.read_buff, self.protocol.buff_size))
  File "/opt/ros/kinetic/lib/python2.7/dist-packages/rosgraph/network.py", line 362, in read_ros_handshake_header
    d = sock.recv(buff_size)
error: [Errno 104] 接続が相手からリセットされました

[rospy.internal][WARNING] 2017-10-04 17:55:50,654: Unknown error initiating TCP/IP socket to ubuntu:53854 (http://ubuntu:43512/): Traceback (most recent call last):
  File "/opt/ros/kinetic/lib/python2.7/dist-packages/rospy/impl/tcpros_base.py", line 557, in connect
    self.read_header()
  File "/opt/ros/kinetic/lib/python2.7/dist-packages/rospy/impl/tcpros_base.py", line 650, in read_header
    self._validate_header(read_ros_handshake_header(sock, self.read_buff, self.protocol.buff_size))
  File "/opt/ros/kinetic/lib/python2.7/dist-packages/rosgraph/network.py", line 362, in read_ros_handshake_header
    d = sock.recv(buff_size)
error: [Errno 104] 接続が相手からリセットされました

[rospy.internal][WARNING] 2017-10-04 17:55:50,753: Unknown error initiating TCP/IP socket to ubuntu:42578 (http://ubuntu:38855/): Traceback (most recent call last):
  File "/opt/ros/kinetic/lib/python2.7/dist-packages/rospy/impl/tcpros_base.py", line 557, in connect
    self.read_header()
  File "/opt/ros/kinetic/lib/python2.7/dist-packages/rospy/impl/tcpros_base.py", line 650, in read_header
    self._validate_header(read_ros_handshake_header(sock, self.read_buff, self.protocol.buff_size))
  File "/opt/ros/kinetic/lib/python2.7/dist-packages/rosgraph/network.py", line 362, in read_ros_handshake_header
    d = sock.recv(buff_size)
error: [Errno 104] 接続が相手からリセットされました

[rospy.internal][WARNING] 2017-10-04 17:55:50,754: Unknown error initiating TCP/IP socket to ubuntu:42578 (http://ubuntu:38855/): Traceback (most recent call last):
  File "/opt/ros/kinetic/lib/python2.7/dist-packages/rospy/impl/tcpros_base.py", line 557, in connect
    self.read_header()
  File "/opt/ros/kinetic/lib/python2.7/dist-packages/rospy/impl/tcpros_base.py", line 650, in read_header
    self._validate_header(read_ros_handshake_header(sock, self.read_buff, self.protocol.buff_size))
  File "/opt/ros/kinetic/lib/python2.7/dist-packages/rosgraph/network.py", line 362, in read_ros_handshake_header
    d = sock.recv(buff_size)
error: [Errno 104] 接続が相手からリセットされました

[rospy.internal][WARNING] 2017-10-04 17:55:50,754: Unknown error initiating TCP/IP socket to ubuntu:42578 (http://ubuntu:38855/): Traceback (most recent call last):
  File "/opt/ros/kinetic/lib/python2.7/dist-packages/rospy/impl/tcpros_base.py", line 557, in connect
    self.read_header()
  File "/opt/ros/kinetic/lib/python2.7/dist-packages/rospy/impl/tcpros_base.py", line 650, in read_header
    self._validate_header(read_ros_handshake_header(sock, self.read_buff, self.protocol.buff_size))
  File "/opt/ros/kinetic/lib/python2.7/dist-packages/rosgraph/network.py", line 362, in read_ros_handshake_header
    d = sock.recv(buff_size)
error: [Errno 104] 接続が相手からリセットされました

[rospy.internal][WARNING] 2017-10-04 17:55:50,754: Unknown error initiating TCP/IP socket to ubuntu:42578 (http://ubuntu:38855/): Traceback (most recent call last):
  File "/opt/ros/kinetic/lib/python2.7/dist-packages/rospy/impl/tcpros_base.py", line 557, in connect
    self.read_header()
  File "/opt/ros/kinetic/lib/python2.7/dist-packages/rospy/impl/tcpros_base.py", line 650, in read_header
    self._validate_header(read_ros_handshake_header(sock, self.read_buff, self.protocol.buff_size))
  File "/opt/ros/kinetic/lib/python2.7/dist-packages/rosgraph/network.py", line 362, in read_ros_handshake_header
    d = sock.recv(buff_size)
error: [Errno 104] 接続が相手からリセットされました

[rospy.internal][WARNING] 2017-10-04 17:55:50,754: Unknown error initiating TCP/IP socket to ubuntu:42578 (http://ubuntu:38855/): Traceback (most recent call last):
  File "/opt/ros/kinetic/lib/python2.7/dist-packages/rospy/impl/tcpros_base.py", line 557, in connect
    self.read_header()
  File "/opt/ros/kinetic/lib/python2.7/dist-packages/rospy/impl/tcpros_base.py", line 650, in read_header
    self._validate_header(read_ros_handshake_header(sock, self.read_buff, self.protocol.buff_size))
  File "/opt/ros/kinetic/lib/python2.7/dist-packages/rosgraph/network.py", line 362, in read_ros_handshake_header
    d = sock.recv(buff_size)
error: [Errno 104] 接続が相手からリセットされました

[rospy.internal][WARNING] 2017-10-04 17:55:50,754: Unknown error initiating TCP/IP socket to ubuntu:42578 (http://ubuntu:38855/): Traceback (most recent call last):
  File "/opt/ros/kinetic/lib/python2.7/dist-packages/rospy/impl/tcpros_base.py", line 557, in connect
    self.read_header()
  File "/opt/ros/kinetic/lib/python2.7/dist-packages/rospy/impl/tcpros_base.py", line 650, in read_header
    self._validate_header(read_ros_handshake_header(sock, self.read_buff, self.protocol.buff_size))
  File "/opt/ros/kinetic/lib/python2.7/dist-packages/rosgraph/network.py", line 362, in read_ros_handshake_header
    d = sock.recv(buff_size)
error: [Errno 104] 接続が相手からリセットされました

[rospy.internal][WARNING] 2017-10-04 17:55:50,756: Unknown error initiating TCP/IP socket to ubuntu:42578 (http://ubuntu:38855/): Traceback (most recent call last):
  File "/opt/ros/kinetic/lib/python2.7/dist-packages/rospy/impl/tcpros_base.py", line 557, in connect
    self.read_header()
  File "/opt/ros/kinetic/lib/python2.7/dist-packages/rospy/impl/tcpros_base.py", line 650, in read_header
    self._validate_header(read_ros_handshake_header(sock, self.read_buff, self.protocol.buff_size))
  File "/opt/ros/kinetic/lib/python2.7/dist-packages/rosgraph/network.py", line 362, in read_ros_handshake_header
    d = sock.recv(buff_size)
error: [Errno 104] 接続が相手からリセットされました

[rospy.internal][WARNING] 2017-10-04 17:55:50,756: Unknown error initiating TCP/IP socket to ubuntu:42578 (http://ubuntu:38855/): Traceback (most recent call last):
  File "/opt/ros/kinetic/lib/python2.7/dist-packages/rospy/impl/tcpros_base.py", line 557, in connect
    self.read_header()
  File "/opt/ros/kinetic/lib/python2.7/dist-packages/rospy/impl/tcpros_base.py", line 650, in read_header
    self._validate_header(read_ros_handshake_header(sock, self.read_buff, self.protocol.buff_size))
  File "/opt/ros/kinetic/lib/python2.7/dist-packages/rosgraph/network.py", line 362, in read_ros_handshake_header
    d = sock.recv(buff_size)
error: [Errno 104] 接続が相手からリセットされました

[rospy.internal][WARNING] 2017-10-04 17:55:50,806: Unknown error initiating TCP/IP socket to ubuntu:51555 (http://ubuntu:38779/): Traceback (most recent call last):
  File "/opt/ros/kinetic/lib/python2.7/dist-packages/rospy/impl/tcpros_base.py", line 557, in connect
    self.read_header()
  File "/opt/ros/kinetic/lib/python2.7/dist-packages/rospy/impl/tcpros_base.py", line 650, in read_header
    self._validate_header(read_ros_handshake_header(sock, self.read_buff, self.protocol.buff_size))
  File "/opt/ros/kinetic/lib/python2.7/dist-packages/rosgraph/network.py", line 362, in read_ros_handshake_header
    d = sock.recv(buff_size)
error: [Errno 104] 接続が相手からリセットされました

[rospy.internal][WARNING] 2017-10-04 17:55:50,807: Unknown error initiating TCP/IP socket to ubuntu:51555 (http://ubuntu:38779/): Traceback (most recent call last):
  File "/opt/ros/kinetic/lib/python2.7/dist-packages/rospy/impl/tcpros_base.py", line 557, in connect
    self.read_header()
  File "/opt/ros/kinetic/lib/python2.7/dist-packages/rospy/impl/tcpros_base.py", line 650, in read_header
    self._validate_header(read_ros_handshake_header(sock, self.read_buff, self.protocol.buff_size))
  File "/opt/ros/kinetic/lib/python2.7/dist-packages/rosgraph/network.py", line 362, in read_ros_handshake_header
    d = sock.recv(buff_size)
error: [Errno 104] 接続が相手からリセットされました

[rospy.internal][WARNING] 2017-10-04 17:55:50,807: Unknown error initiating TCP/IP socket to ubuntu:51555 (http://ubuntu:38779/): Traceback (most recent call last):
  File "/opt/ros/kinetic/lib/python2.7/dist-packages/rospy/impl/tcpros_base.py", line 557, in connect
    self.read_header()
  File "/opt/ros/kinetic/lib/python2.7/dist-packages/rospy/impl/tcpros_base.py", line 650, in read_header
    self._validate_header(read_ros_handshake_header(sock, self.read_buff, self.protocol.buff_size))
  File "/opt/ros/kinetic/lib/python2.7/dist-packages/rosgraph/network.py", line 362, in read_ros_handshake_header
    d = sock.recv(buff_size)
error: [Errno 104] 接続が相手からリセットされました

[rospy.internal][WARNING] 2017-10-04 17:55:50,807: Unknown error initiating TCP/IP socket to ubuntu:51555 (http://ubuntu:38779/): Traceback (most recent call last):
  File "/opt/ros/kinetic/lib/python2.7/dist-packages/rospy/impl/tcpros_base.py", line 557, in connect
    self.read_header()
  File "/opt/ros/kinetic/lib/python2.7/dist-packages/rospy/impl/tcpros_base.py", line 650, in read_header
    self._validate_header(read_ros_handshake_header(sock, self.read_buff, self.protocol.buff_size))
  File "/opt/ros/kinetic/lib/python2.7/dist-packages/rosgraph/network.py", line 362, in read_ros_handshake_header
    d = sock.recv(buff_size)
error: [Errno 104] 接続が相手からリセットされました

[rospy.internal][WARNING] 2017-10-04 17:55:50,807: Unknown error initiating TCP/IP socket to ubuntu:51555 (http://ubuntu:38779/): Traceback (most recent call last):
  File "/opt/ros/kinetic/lib/python2.7/dist-packages/rospy/impl/tcpros_base.py", line 557, in connect
    self.read_header()
  File "/opt/ros/kinetic/lib/python2.7/dist-packages/rospy/impl/tcpros_base.py", line 650, in read_header
    self._validate_header(read_ros_handshake_header(sock, self.read_buff, self.protocol.buff_size))
  File "/opt/ros/kinetic/lib/python2.7/dist-packages/rosgraph/network.py", line 362, in read_ros_handshake_header
    d = sock.recv(buff_size)
error: [Errno 104] 接続が相手からリセットされました

[rospy.internal][WARNING] 2017-10-04 17:55:50,807: Unknown error initiating TCP/IP socket to ubuntu:51555 (http://ubuntu:38779/): Traceback (most recent call last):
  File "/opt/ros/kinetic/lib/python2.7/dist-packages/rospy/impl/tcpros_base.py", line 557, in connect
    self.read_header()
  File "/opt/ros/kinetic/lib/python2.7/dist-packages/rospy/impl/tcpros_base.py", line 650, in read_header
    self._validate_header(read_ros_handshake_header(sock, self.read_buff, self.protocol.buff_size))
  File "/opt/ros/kinetic/lib/python2.7/dist-packages/rosgraph/network.py", line 362, in read_ros_handshake_header
    d = sock.recv(buff_size)
error: [Errno 104] 接続が相手からリセットされました

[rospy.internal][WARNING] 2017-10-04 17:55:50,807: Unknown error initiating TCP/IP socket to ubuntu:51555 (http://ubuntu:38779/): Traceback (most recent call last):
  File "/opt/ros/kinetic/lib/python2.7/dist-packages/rospy/impl/tcpros_base.py", line 557, in connect
    self.read_header()
  File "/opt/ros/kinetic/lib/python2.7/dist-packages/rospy/impl/tcpros_base.py", line 650, in read_header
    self._validate_header(read_ros_handshake_header(sock, self.read_buff, self.protocol.buff_size))
  File "/opt/ros/kinetic/lib/python2.7/dist-packages/rosgraph/network.py", line 362, in read_ros_handshake_header
    d = sock.recv(buff_size)
error: [Errno 104] 接続が相手からリセットされました

[rospy.internal][WARNING] 2017-10-04 17:55:50,808: Unknown error initiating TCP/IP socket to ubuntu:51555 (http://ubuntu:38779/): Traceback (most recent call last):
  File "/opt/ros/kinetic/lib/python2.7/dist-packages/rospy/impl/tcpros_base.py", line 557, in connect
    self.read_header()
  File "/opt/ros/kinetic/lib/python2.7/dist-packages/rospy/impl/tcpros_base.py", line 650, in read_header
    self._validate_header(read_ros_handshake_header(sock, self.read_buff, self.protocol.buff_size))
  File "/opt/ros/kinetic/lib/python2.7/dist-packages/rosgraph/network.py", line 362, in read_ros_handshake_header
    d = sock.recv(buff_size)
error: [Errno 104] 接続が相手からリセットされました

[rospy.internal][WARNING] 2017-10-04 17:55:50,808: Unknown error initiating TCP/IP socket to ubuntu:51555 (http://ubuntu:38779/): Traceback (most recent call last):
  File "/opt/ros/kinetic/lib/python2.7/dist-packages/rospy/impl/tcpros_base.py", line 557, in connect
    self.read_header()
  File "/opt/ros/kinetic/lib/python2.7/dist-packages/rospy/impl/tcpros_base.py", line 650, in read_header
    self._validate_header(read_ros_handshake_header(sock, self.read_buff, self.protocol.buff_size))
  File "/opt/ros/kinetic/lib/python2.7/dist-packages/rosgraph/network.py", line 362, in read_ros_handshake_header
    d = sock.recv(buff_size)
error: [Errno 104] 接続が相手からリセットされました

[rospy.internal][WARNING] 2017-10-04 17:55:50,808: Unknown error initiating TCP/IP socket to ubuntu:51555 (http://ubuntu:38779/): Traceback (most recent call last):
  File "/opt/ros/kinetic/lib/python2.7/dist-packages/rospy/impl/tcpros_base.py", line 557, in connect
    self.read_header()
  File "/opt/ros/kinetic/lib/python2.7/dist-packages/rospy/impl/tcpros_base.py", line 650, in read_header
    self._validate_header(read_ros_handshake_header(sock, self.read_buff, self.protocol.buff_size))
  File "/opt/ros/kinetic/lib/python2.7/dist-packages/rosgraph/network.py", line 362, in read_ros_handshake_header
    d = sock.recv(buff_size)
error: [Errno 104] 接続が相手からリセットされました

[rospy.internal][WARNING] 2017-10-04 17:55:50,808: Unknown error initiating TCP/IP socket to ubuntu:51555 (http://ubuntu:38779/): Traceback (most recent call last):
  File "/opt/ros/kinetic/lib/python2.7/dist-packages/rospy/impl/tcpros_base.py", line 557, in connect
    self.read_header()
  File "/opt/ros/kinetic/lib/python2.7/dist-packages/rospy/impl/tcpros_base.py", line 650, in read_header
    self._validate_header(read_ros_handshake_header(sock, self.read_buff, self.protocol.buff_size))
  File "/opt/ros/kinetic/lib/python2.7/dist-packages/rosgraph/network.py", line 362, in read_ros_handshake_header
    d = sock.recv(buff_size)
error: [Errno 104] 接続が相手からリセットされました

[rospy.internal][WARNING] 2017-10-04 17:55:50,808: Unknown error initiating TCP/IP socket to ubuntu:51555 (http://ubuntu:38779/): Traceback (most recent call last):
  File "/opt/ros/kinetic/lib/python2.7/dist-packages/rospy/impl/tcpros_base.py", line 557, in connect
    self.read_header()
  File "/opt/ros/kinetic/lib/python2.7/dist-packages/rospy/impl/tcpros_base.py", line 650, in read_header
    self._validate_header(read_ros_handshake_header(sock, self.read_buff, self.protocol.buff_size))
  File "/opt/ros/kinetic/lib/python2.7/dist-packages/rosgraph/network.py", line 362, in read_ros_handshake_header
    d = sock.recv(buff_size)
error: [Errno 104] 接続が相手からリセットされました

[rospy.internal][WARNING] 2017-10-04 17:55:50,808: Unknown error initiating TCP/IP socket to ubuntu:51555 (http://ubuntu:38779/): Traceback (most recent call last):
  File "/opt/ros/kinetic/lib/python2.7/dist-packages/rospy/impl/tcpros_base.py", line 557, in connect
    self.read_header()
  File "/opt/ros/kinetic/lib/python2.7/dist-packages/rospy/impl/tcpros_base.py", line 650, in read_header
    self._validate_header(read_ros_handshake_header(sock, self.read_buff, self.protocol.buff_size))
  File "/opt/ros/kinetic/lib/python2.7/dist-packages/rosgraph/network.py", line 362, in read_ros_handshake_header
    d = sock.recv(buff_size)
error: [Errno 104] 接続が相手からリセットされました

[rospy.internal][WARNING] 2017-10-04 17:55:50,809: Unknown error initiating TCP/IP socket to ubuntu:51555 (http://ubuntu:38779/): Traceback (most recent call last):
  File "/opt/ros/kinetic/lib/python2.7/dist-packages/rospy/impl/tcpros_base.py", line 557, in connect
    self.read_header()
  File "/opt/ros/kinetic/lib/python2.7/dist-packages/rospy/impl/tcpros_base.py", line 650, in read_header
    self._validate_header(read_ros_handshake_header(sock, self.read_buff, self.protocol.buff_size))
  File "/opt/ros/kinetic/lib/python2.7/dist-packages/rosgraph/network.py", line 362, in read_ros_handshake_header
    d = sock.recv(buff_size)
error: [Errno 104] 接続が相手からリセットされました

